<?xml version='1.0'?>
<robot name="box_ropot" xmlns:xacro="http://www.ros.org/wiki/xacro">
<xacro:include filename="$(find urdf_trial_discription)/urdf/plugin.gazebo" />
<link name="base_link">
   
</link>
    <joint name="base_link_joint" type="fixed">
        <origin xyz="0.0 0.0 0.0" rpy="0.0 0.0 0.0"/>
        <parent link="base_link"/>
        <child link="base_plate"/>
        <axis xyz="0.0 0.0 0.0"/>
        <limit lower="0.0" upper="0.0" effort="0.0" velocity="0.0"/>
    </joint>
<link name="base_plate">
    <inertial>
        <origin xyz="0.0 0.0 0.0" rpy="0.0 0.0 0.0"/>
        <mass value="15.0"/>
        <inertia ixx="0.0" ixy="0.0" ixz="0.0" iyy="0.1" iyz="0.0" izz="0.0"/>
    </inertial>
    <visual name="plate_visual">
        <origin xyz="0.0 0.0 0.05" rpy="1.5707 0.0 0.0"/>
        <geometry>
            <box size=".2 .026 .3"/>
        </geometry>
        <material name="orange">
            <color rgba="1 1 1 1"/>
            <texture filename=""/>
        </material>
    </visual>
    <collision>
        <origin xyz="0.0 0.0 0.0" rpy="0.0 0.0 0.0"/>
        <geometry>
            <box size=".2 .026 .3"/>
        </geometry>
    </collision>
</link>    
<link name="upper_plate">
    <inertial>
        <origin xyz="0.0 0.0 0.0" rpy="0.0 0.0 0.0"/>
        <mass value="15.0"/>
        <inertia ixx="0.0" ixy="0.0" ixz="0.0" iyy="0.0" iyz="0.0" izz="0.0"/>
    </inertial>
    <visual name="upper_plate_visual">
        <origin xyz="0.0 0.0 0.09" rpy="1.5707 0.0 0.0"/>
        <geometry>
            <box size=".2 .019 .3"/>
        </geometry>
        <material name="orange">
            <color rgba="1 1 1 1"/>
            <texture filename=""/>
        </material>
    </visual>
    <collision>
        <origin xyz="0.0 0.0 0.09" rpy="1.5707 0.0 0.0"/>

        <geometry>
            <box size=".2 .019 .3"/>
        </geometry>
    </collision>
</link>    
<joint name="upper_plate_joint" type="fixed">
    <origin xyz="0.0 0.0 0.05" rpy="0 0.0 0.0"/>
    <parent link="base_link"/>
    <child link="upper_plate"/>
    <axis xyz="0.0 0.0 0.0"/>
    <limit lower="0.0" upper="0.0" effort="0.0" velocity="0.0"/>
</joint>
<link name="left__back_wheel">
    <inertial>
        <origin xyz="0.11 0.1 0.0" rpy="0 0.0 0"/>
        <mass value="0.3"/>
        <inertia ixx="0.0" ixy="0.0" ixz="0.0" iyy="0.0" iyz="0.0" izz="0.0"/>
    </inertial>
    <visual name="left__back_wheel_visual">
        <origin xyz="0.0 0.0 0.0" rpy="0 1.5707 1.5707"/>
        <geometry>
            <cylinder radius="0.04" length="0.02"/>
        </geometry>
        <material name="">
            <color rgba="125.0 0.0 0.0 1.0"/>
            <texture filename=""/>
        </material>
    </visual>
    <collision>
        <origin xyz="0.0 0.0 0.0" rpy="0 0 0.0"/>
        <geometry>
             <cylinder radius="0.04" length="0.02"/>
        </geometry>
    </collision>
</link>
<joint name="left__back_wheel_joint" type="continuous"> 
    <origin xyz="-0.11 -0.06 0.04" rpy="0 0.0 -1.57"/>
    <parent link="base_plate"/>
    <child link="left__back_wheel"/>
    <axis xyz="0.0 0.0 0.0"/>
    <limit lower="0.0" upper="0.0" effort="0.0" velocity="0.0"/>
</joint>

<link name="right_back_wheel">
    <inertial>
        <origin xyz="0.0 0.0 0.0" rpy="0 0.0 0.0"/>
        <mass value="0.3"/>
        <inertia ixx="0.0" ixy="0.0" ixz="0.0" iyy="0.0" iyz="0.0" izz="0.0"/>
    </inertial>
    <visual name="right_back_wheel_visual">
        <origin xyz="0.0 0.0 0.0" rpy="0 1.5707 0 "/>
        <geometry>
               <cylinder radius="0.04" length="0.02"/>
         
        </geometry>
        <material name="">
            <color rgba="125.0 0.0 0.0 1.0"/>
            <texture filename=""/>
        </material>
    </visual>
    <collision>
          <origin xyz="0.0 0.0 0.0" rpy="0 1.5707 0 "/>
          <geometry>
           <cylinder radius="0.04" length="0.02"/>
        </geometry>
    </collision>
</link>
<joint name="right_back_wheel_joint" type="continuous">
    <origin xyz="-0.11 0.06 0.04" rpy="0.0 0 0"/>
    <parent link="base_plate"/>
    <child link="right_back_wheel"/>
    <axis xyz="0.0 0.0 0.0"/>
    <limit lower="0.0" upper="0.0" effort="0.0" velocity="0.0"/>
</joint>
<link name="right_front_wheel">
    <inertial>
        <origin xyz="0.0 0.0 0.0" rpy="0 0.0 0.0"/>
        <mass value="0.3"/>
        <inertia ixx="0.0" ixy="0.0" ixz="0.0" iyy="0.0" iyz="0.0" izz="0.0"/>
    </inertial>
    <visual name="right_front_wheel_visual">
        <origin xyz="0.0 0.0 0.0" rpy="0 1.5707 0 "/>
        <geometry>
               <cylinder radius="0.04" length="0.02"/>
         
        </geometry>
        <material name="">
            <color rgba="125.0 0.0 0.0 1.0"/>
            <texture filename=""/>
        </material>
    </visual>
    <collision>
        <origin xyz="0.0 0.0 0.0" rpy="0 1.5707 0 "/>
        <geometry>
               <cylinder radius="0.04" length="0.02"/>
        </geometry>
    </collision>
</link>

<joint name="right_front_wheel_joint" type="continuous">
    <origin xyz="0.11 -0.06 0.04" rpy="0.0 0.0 0.0"/>
    <parent link="base_plate"/>
    <child link="right_front_wheel"/>
    <axis xyz="0.0 0.0 0.0"/>
    <limit lower="0.0" upper="0.0" effort="0.0" velocity="0.0"/>
</joint>

<link name="left_front_wheel">
    <inertial>
        <origin xyz="0.0 0.0 0.0" rpy="0 0.0 0.0"/>
        <mass value="0.4"/>
        <inertia ixx="0.0" ixy="0.0" ixz="0.0" iyy="0.0" iyz="0.0" izz="0.0"/>
    </inertial>
    <visual name="left_front_wheel_visual">
        <origin xyz="0.0 0.0 0.0" rpy="0 1.5707 0.0"/>
        <geometry>
            <cylinder radius="0.04" length="0.02"/>
        </geometry>
        <material name="">
            <color rgba="125.0 0.0 0.0 1.0"/>
            <texture filename=""/>
        </material>
    </visual>
    <collision>
        <origin xyz="0.0 0.0 0.0" rpy="0 1.5707 0.0"/>
        <geometry>
            <cylinder radius="0.04" length="0.02"/>
        </geometry>
    </collision>
</link>
<joint name="left_front_wheel_joint" type="continuous">
    <origin xyz="0.11 0.06 0.04" rpy="0.0 0.0 0.0"/>
    <parent link="base_plate"/>
    <child link="left_front_wheel"/>
    <axis xyz="0.0 0.0 0.0"/>
    <limit lower="0.0" upper="0.0" effort="0.0" velocity="0.0"/>
</joint>
<link name="left_back_culom">
    <inertial>
        <origin xyz="0.0  0.0 0.0" rpy="0 0.0 0.0"/>
        <mass value="0.0"/>
        <inertia ixx="0.0" ixy="0.0" ixz="0.0" iyy="0.0" iyz="0.0" izz="0.0"/>
    </inertial>
    <visual name="">
        <origin xyz="0.0 0.0 0.0" rpy="0 0 1.5707"/><!--.53+ .5*cylinder length-->
        <geometry>
            <cylinder radius="0.005" length="0.09"/>
        </geometry>
        <material name="left_back_culom_visual">
            <color rgba="1.0 0.0 0.0 1.0"/>
            <texture filename=""/>
        </material>
    </visual>
    <collision>
         <origin xyz="0.0 0.0 0.0" rpy="0 1.5707 1.5707"/>
         <geometry>
             <cylinder radius="0.005" length="0.08"/>
        </geometry>
    </collision>
</link>
<joint name="upper_left_back_culom_joint" type="fixed">
    <origin xyz="-0.07 -0.1 0.1" rpy="0.0 0.0 0.0"/>
    <parent link="base_plate"/>
    <child link="left_back_culom"/>
    <axis xyz="0.0 0.0 0.0"/>
    <limit lower="0.0" upper="0.0" effort="0.0" velocity="0.0"/>
</joint>

<link name="right_back_colum">
    <inertial>
        <origin xyz="0.0 0.0 0.0" rpy="0 0.0 0.0"/>
        <mass value="0.0"/>
        <inertia ixx="0.0" ixy="0.0" ixz="0.0" iyy="0.0" iyz="0.0" izz="0.0"/>
    </inertial>
    <visual name="">
        <origin xyz="0.0 0.0 0.0" rpy="0 0 1.5707 "/>
        <geometry>
            <cylinder radius="0.005" length="0.09"/>
         
        </geometry>
        <material name="right_back_colum_visual">
            <color rgba="1.0 0.0 0.0 1.0"/>
            <texture filename=""/>
        </material>
    </visual>
    <collision>
        <origin xyz="0.0 0.0 0.0" rpy="0 0 1.5707 "/>
        <geometry>
            <cylinder radius="0.005" length="0.09"/>
        </geometry>
    </collision>
</link>
<joint name="upper_right_back_culom_joint" type="fixed">
    <origin xyz="0.07 -.1 0.1" rpy="0.0 0.0 0.0"/>
    <parent link="base_plate"/>
    <child link="right_back_colum"/>
    <axis xyz="0.0 0.0 0.0"/>
    <limit lower="0.0" upper="0.0" effort="0.0" velocity="0.0"/>
</joint>


<link name="left__front_colum">
    <inertial>
        <origin xyz="0.0 0.0 0.0" rpy="0 0.0 0.0"/>
        <mass value="0.0"/>
        <inertia ixx="0.0" ixy="0.0" ixz="0.0" iyy="0.0" iyz="0.0" izz="0.0"/>
    </inertial>
    <visual name="">
        <origin xyz="0.0 0.0 0.0" rpy="0 0 0"/>
        <geometry>
            <cylinder radius="0.005" length="0.09"/>
        </geometry>
        <material name="left__front_colum_visual">
            <color rgba="1.0 0.0 0.0 1.0"/>
            <texture filename=""/>
        </material>
    </visual>
    <collision>
        <origin xyz="0.0 0.0 0.0" rpy="0 0 0"/>
        <geometry>
            <cylinder radius="0.005" length="0.08"/>
        </geometry>
    </collision>
</link>
<joint name="upper_left_front_culom_joint" type="fixed">
    <origin xyz="0.07 .1 0.1" rpy="0.0 0.0 0.0"/>
    <parent link="base_plate"/>
    <child link="left__front_colum"/>
    <axis xyz="0.0 0.0 0.0"/>
    <limit lower="0.0" upper="0.0" effort="0.0" velocity="0.0"/>
</joint>
<link name="right_front_colum">
    <inertial>
        <origin xyz="0.0 0.0 0.0" rpy="0 0.0 0.0"/>
        <mass value="0.0"/>
        <inertia ixx="0.0" ixy="0.0" ixz="0.0" iyy="0.0" iyz="0.0" izz="0.0"/>
    </inertial>
    <visual name="">
        <origin xyz="0.0 0.0 0.0" rpy="0 0 0 "/>
        <geometry>
            <cylinder radius="0.005" length="0.09"/>
         
        </geometry>
        <material name="right_front_colum_visual">
            <color rgba="1.0 0.0 0.0 1.0"/>
            <texture filename=""/>
        </material>
    </visual>
    <collision>
        <origin xyz="0.0 0.0 0.0" rpy="0 0 0.0"/>
        <geometry>
            <cylinder radius="0.005" length="0.08"/>
        </geometry>
    </collision>
</link>
<joint name="upper_right_front_culom_joint" type="fixed">
    <origin xyz="-0.07 .1 0.1" rpy="0.0 0.0 0.0"/>
    <parent link="base_plate"/>
    <child link="right_front_colum"/>
    <axis xyz="0.0 0.0 0.0"/>
    <limit lower="0.0" upper="0.0" effort="0.0" velocity="0.0"/>
</joint>

<link name="hokuyo">
    <inertial>
        <origin xyz="0.0 0.0 0.0" rpy="0.0 0.0 0.0"/>
        <mass value="0.0"/>
        <inertia ixx="0.0" ixy="0.0" ixz="0.0" iyy="0.0" iyz="0.0" izz="0.0"/>
    </inertial>
    <visual name="hokuyo_visual">
        <origin xyz="0.0 .0 0.0" rpy="0.0 0.0 0.0"/>
        <geometry>
           <cylinder radius=".04" length=".05"/>

        </geometry>
        <material name="">
            <color rgba="0 1 1 .6"/>
            <texture filename=""/>
        </material>
    </visual>
    <collision>
        <origin xyz="0.0 .145 0.1" rpy="0.0 0.0 0.0"/>
        <geometry>
            <box size="0.05 0.05 0.05"/>
        </geometry>
    </collision>
</link>
<joint name="hokuyo_joint" type="fixed">
    <origin xyz="0.0 .0 0.12" rpy="0.0 0.0 0.0"/>
    <parent link="upper_plate"/>
    <child link="hokuyo"/>
    <axis xyz="0.0 0.0 0.0"/>
    <limit lower="0.0" upper="0.0" effort="0.0" velocity="0.0"/>
</joint>

</robot>
